Workbook

Sheet sheet1
A1: 基地 | B1: SN | C1: 机型名 | D1: 套餐名 | E1: 订单号 | F1: 报错时间 | G1: 当前工站 | H1: 报错测试项 | I1: 日志内容 | J1: 是否录入维修 | K1: 不良维度3 | L1: 维修动作 | M1: 分类 | N1: 备注 | O1: 处理人
A2: 9000 | B2: 6102265104304987 | C2: G230-DM-2 | D2: B8621-IBDD2O | E2: 30228728 | F2: 2026-05-10 11:58:21 | G2: 老化测试 | H2: [字节]Changsha reboot 测试 | I2: Program KILLED BY TIMEOUT Killed by timeout max second 3600
A3: 9000 | B3: 6102265104304951 | C3: G230-DM-2 | D3: B8621-IBDD2O | E3: 30228526 | F3: 2026-05-10 13:00:25 | G3: 老化测试 | H3: [字节]Changsha BIOS BMC恢复默认设置 | I3: Program KILLED BY TIMEOUT Killed by timeout max second 600
A4: 9000 | B4: 6102228404313006 | C4: G220B-2G1BxxM-T | D4: SH10T1-3E42GA-S | E4: 30228126 | F4: 2026-05-10 16:45:50 | G4: 初检前测 | H4: [客户定制][字节]黑白名单检查_前测 | I4: 7 05102026 080229 Power Supply B0PSU2Supply Power Supply AC lost Deasserted 8 05102026 080229 Power Supply B0PSU2Supply AC outofrange but present Deasserted 9 05102026 080232 Power Supply B0PSU0Supply Power Supply AC lost Deasserted a 05102026 080232 Power Supply B0PSU0Supply AC outofrange but present Deasserted 3 05102026 080116 Power Supply B0PSU0Supply Power Supply AC lost Asserted 5 05102026 080116 Power Supply B0PSU2Supply Power Supply AC lost As
A5: 9000 | B5: 6102228404310028 | C5: G220B-2G1BxxM-T | D5: SH10T1-3E42GA-S | E5: 30228124 | F5: 2026-05-09 07:13:18 | G5: 初检前测 | H5: [客户定制][字节]黑白名单检查_前测 | I5: import 01000 15b3197b LinkCap 320GTs x16 LinkSta 320GTs x16 import 02000 15b3197b LinkCap 320GTs x16 LinkSta 320GTs x16 import 02030 15b3197b LinkCap 320GTs x16 LinkSta 320GTs x16 import 03000 15b3a2dc LinkCap 320GTs x16 LinkSta 320GTs x16 import 03001 15b3a2dc LinkCap 320GTs x16 LinkSta 320GTs x16 import 04000 15b3197b LinkCap 320GTs x16 LinkSta 320GTs x16 import 05000 15b3197b LinkCap 320GTs x2 LinkSta 80GTs x2 | J5: 是 | K5: 停用字节_黑白名单检查_前测_PCIE链路报错 | L5: =VLOOKUP(B5,Sheet2!F:Z,12) -> 更换数据线 | M5: 疑似接触不良问题
A6: 9000 | B6: 6102117004309929 | C6: G220-BM | D6: S80D1-I9ED2M | E6: 30228519 | F6: 2026-05-09 10:39:05 | G6: 老化测试 | H6: [客户定制][字节] EGS REBOOT测试 2LOOP | I6: Sat May 9 103751 2026 smpapictimerinterrupt0x680x120 Sat May 9 103751 2026 apictimerinterrupt0xf0x20 Sat May 9 103751 2026 r8152 2210 eth2 Tx timeout May 9 103751 bytedancehostv13 kernel 56368874 C9 smpapictimerinterrupt0x680x120 May 9 103751 bytedancehostv13 kernel 56368875 C9 apictimerinterrupt0xf0x20 May 9 103751 bytedancehostv13 kernel 56385022 C9 r8152 2210 eth2 Tx timeout check black list fail LAST LOOP Check fail
A7: 9000 | B7: 6102117004309930 | C7: G220-BM | D7: S80D1-I9ED2M | E7: 30228519 | F7: 2026-05-09 10:42:15 | G7: 老化测试 | H7: [客户定制][字节] EGS AC测试 10LOOP | I7: Sat May 9 104138 2026 xhcihcd 000000140 WARN Set TR Deq Ptr cmd failed due to incorrect slot or ep state May 9 104139 bytedancehostv13 kernel 107264522 C39 xhcihcd 000000140 WARN Set TR Deq Ptr cmd failed due to incorrect slot or ep state check black list first fail custom toutiao task fail
A8: 9000 | B8: 6102117004312875 | C8: G220-BM | D8: S80D1-I9ED2M | E8: 30228520 | F8: 2026-05-10 07:24:15 | G8: 老化测试 | H8: [客户定制][字节] EGS AC测试 10LOOP | I8: Sun May 10 072239 2026 r8152 2210 eth2 Get ether addr fail Sun May 10 072239 2026 smpapictimerinterrupt0x680x120 Sun May 10 072239 2026 apictimerinterrupt0xf0x20 Sun May 10 072239 2026 r8152 2210 eth2 Tx timeout May 10 072239 bytedancehostv13 kernel 43532717 C11 smpapictimerinterrupt0x680x120 May 10 072239 bytedancehostv13 kernel 43542131 C11 apictimerinterrupt0xf0x20 May 10 072239 bytedancehostv13 kernel 43548249 C11 r8152 2210 eth2 Tx timeout
A9: 9000 | B9: 6102265104304955 | C9: G230-DM-2 | D9: B8621-IBDD2O | E9: 30228526 | F9: 2026-05-10 13:00:49 | G9: 老化测试 | H9: [字节]Changsha BIOS BMC恢复默认设置 | I9: Program KILLED BY TIMEOUT Killed by timeout max second 600
A10: 9000 | B10: 6102228404304258 | C10: G220B-2G1BxxM-T | D10: SH10T1-3E42GA-S | E10: 30228122 | F10: 2026-05-10 22:54:53 | G10: 老化初检 | H10: [客户定制][字节]MEMTESTER与FIO测试 | I10: 9 05102026 040649 Processor CPU1Status Correctable machine check error Asserted 9 05102026 040649 Processor CPU1Status Correctable machine check error Asserted 45 05102026 143849 Power Supply RedundantPSU Redundancy Lost Deasserted 41 05102026 143815 Power Supply RedundantPSU Redundancy Lost Asserted 45 05102026 143849 Power Supply RedundantPSU Redundancy Lost Deasserted 46 05102026 143849 Power Supply RedundantPSU Redundancy Lost Deasserted
A11: 9000 | B11: 6102117004312852 | C11: G220-BM | D11: S80D1-I9ED2M | E11: 30228520 | F11: 2026-05-09 20:05:34 | G11: 初检前测 | H11: 硬件信息检查 | I11: PCI1 Input SN 24003530 device 0x10210x15B30x00210x15B3 Class NA Count 1 PCI Local addr 000017000 LnkCap 32GTsx16 LnkSta 32GTsx8 CPU LnkCap 32GTsx16 not equal PCI Local addr 000017001 LnkCap 32GTsx16 LnkSta 32GTsx8 CPU LnkCap 32GTsx16 not equal PCI1 Local Count 1 PCI1 check result fail PCI check result fail
A12: 9000 | B12: 6102228404322547 | C12: G220B-2G1BxxM-T | D12: SH10T1-3E42GA-S | E12: 30227559 | F12: 2026-05-14 14:36:09 | G12: 初检前测 | H12: [客户定制][字节]黑白名单检查_前测 | I12: 17 05142026 061902 Critical Interrupt PCIEStatus Bus Correctable error BDF 000000 Deasserted 16 05142026 061125 Critical Interrupt PCIEStatus Bus Correctable error BDF 4a0100 Asserted 17 05142026 061902 Critical Interrupt PCIEStatus Bus Correctable error BDF 000000 Deasserted 16 05142026 061125 Critical Interrupt PCIEStatus Bus Correctable error BDF 4a0100 Asserted 17 05142026 061902 Critical Interrupt PCIEStatus Bus Correctable error BDF 000000 Deasserted
A13: 9000 | B13: 6102228404322539 | C13: G220B-2G1BxxM-T | D13: SH10T1-3E42GA-S | E13: 30227559 | F13: 2026-05-14 15:10:06 | G13: 老化初检 | H13: [客户定制][字节]黑白名单检查_前测 | I13: 6 05142026 000851 OEM record cd 00b3dd bacc02030000 Current PCIe devices do not match PCIe topology e 05142026 003833 OEM record cd 00b3dd bacc02030000 Current PCIe devices do not match PCIe topology 3a 05142026 012554 OEM record cd 00b3dd bacc02030000 Current PCIe devices do not match PCIe topology 4d 05142026 015153 OEM record cd 00b3dd bacc02030000 Current PCIe devices do not match PCIe topology 63 05142026 023741 OEM record cd 00b3dd bacc02030000 Current PCI
A14: 9000 | B14: 6102228404315789 | C14: G220B-2G1BxxM-T | D14: SH10T1-3E42GA-S | E14: 30228128 | F14: 2026-05-10 11:56:36 | G14: 初检前测 | H14: [客户定制][字节]黑白名单检查_前测 | I14: Sun May 10 114412 2026 r8152 2210 Direct firmware load for rtlnicrtl8153a3fw failed with error 2 Sun May 10 114412 2026 r8152 2210 Direct firmware load for rtlnicrtl8153a3fw failed with error 2 Sun May 10 114412 2026 r8152 2210 Direct firmware load for rtlnicrtl8153a3fw failed with error 2
A15: 9000 | B15: 6102265104304987 | C15: G230-DM-2 | D15: B8621-IBDD2O | E15: 30228728 | F15: 2026-05-10 18:01:55 | G15: 老化测试 | H15: [字节][QTBQC]HOST关机 | I15: Program KILLED BY TIMEOUT Killed by timeout max second 3600
A16: 9000 | B16: 6102228404301155 | C16: G220B-2G1BxxM-T | D16: SH10T1-3E42GA-S | E16: 30228120 | F16: 2026-05-10 22:10:28 | G16: 老化测试 | H16: [客户定制][字节][TMS/JHS]压力测试 | I16: 230 Bus Correctable error 20260510 200818 mainBlackListTest INFO line616 cmd lsblk ndp awk nvmediskprint 1 20260510 200818 mainBlackListTest INFO line48 Run Cmd lsblk ndp awk nvmediskprint 1 20260510 200818 mainBlackListTest INFO line54 Return 0 20260510 200818 mainBlackListTest INFO line59 output devnvme1n1 Health test FAIL ERROR Health check fail RESULT FAIL End at 20260510 200842 20260510 200907info PCIE 20260510 200907info PACKAGE SH10T13E42GAS FAIL | J16: 是 | K16: 字节_[客户定制][字节][TMS/JHS]压力测试_GPU链路报错 | L16: =VLOOKUP(B16,Sheet2!F:Z,12,0) -> 重插数据线 | M16: 疑似接触不良问题
A17: 9000 | B17: 6102228404315807 | C17: G220-BM | E17: 30228128 | F17: 2026-05-10 23:28:32 | G17: 老化初检 | H17: [客户定制][字节]BF3串口通信检查 | I17: All serial port test FAIL test result FAIL RESULT FAIL
A18: 9000 | B18: 6102228404315806 | C18: G220-BM | E18: 30228128 | F18: 2026-05-10 23:28:32 | G18: 老化初检 | H18: [客户定制][字节]BF3串口通信检查 | I18: All serial port test FAIL test result FAIL RESULT FAIL
A19: 9000 | B19: 6102265104305009 | C19: G230-DM-2 | D19: B8621-IBDD2O | E19: 30228527 | F19: 2026-05-11 00:12:05 | G19: 老化测试 | H19: [客户定制][字节]混合压测1H与REBOOT 4LOOP | I19: COMMON BOARD ERROR FUNCTION Black list check fail fail type sel dmessage message | J19: 是 | K19: 字节_[客户定制][字节]混合压测1H与REBOOT 4LOOP_内存Correctable ECC | L19: =VLOOKUP(B19,Sheet2!F:Z,12,0) -> 更换内存 | M19: 物料问题
A20: 9000 | B20: 6102117004312817 | C20: G220-BM | D20: S80D1-I9ED2M | E20: 30228520 | F20: 2026-05-11 00:19:49 | G20: 老化测试 | H20: [客户定制][字节] EGS AC测试 3LOOP | I20: AC timeout
A21: 9000 | B21: 6102228404315821 | C21: G220-BM | E21: 30228128 | F21: 2026-05-11 03:54:06 | G21: 老化初检 | H21: [客户定制][字节]BF3串口通信检查 | I21: Failed to boot NETNICP1IPV6 Start PXE over IPv4 Send DHCP DISCOVER Client MAC 6431360F53EA Recv DHCP OFFER Client MAC 6431360F53EA Send DHCP REQUEST Client MAC 6431360F53EA Failed to boot NETNICP0IPV4 Start PXE over IPv4 Send DHCP DISCOVER Client MAC 6431360F53EB Recv DHCP OFFER Client MAC 6431360F53EBtimeout didnt get login message Alert serial devttyUSB0 not existskip test All serial port test FAIL test result FAIL RESULT FAIL
A22: 9000 | B22: 6102228404301183 | C22: G220B-2G1BxxM-T | D22: SH10T1-3E42GA-S | E22: 30228120 | F22: 2026-05-11 04:44:07 | G22: 老化初检 | H22: [客户定制][字节]EGS混合压测 6H | I22: Mon May 11 043044 2026 00 BAD 00 ff ff ff ff ff ff 00 4e ad 23 c1 01 00 00 00 Mon May 11 043044 2026 00 BAD 1f 1f 01 03 0e 34 20 78 ea ee 91 a3 54 4c 99 26 Mon May 11 043044 2026 00 BAD 0f 50 54 ff ff 80 a9 40 81 80 71 86 95 00 b3 00 Mon May 11 043044 2026 00 BAD d1 c0 81 00 d1 00 64 19 00 40 41 00 26 30 18 88 Mon May 11 043044 2026 00 BAD 36 00 06 44 21 00 00 1a 00 00 00 fd 00 31 56 1d Mon May 11 043044 2026 00 BAD 5e 15 00 0a 20 20 20 20 20 20 00 00 00 fc 00 4b
A23: 9000 | B23: 6102265104304943 | C23: G230-DM-2 | D23: B8621-IBDD2O | E23: 30228526 | F23: 2026-05-11 05:16:03 | G23: 综检后测 | H23: [字节][擎天]人机交互 | I23: COMMON BOARD ERROR BMC Get bmc sel info fail
A24: 9000 | B24: 6102265104305004 | C24: G230-DM-2 | D24: B8621-IBDD2O | E24: 30228731 | F24: 2026-05-11 07:39:45 | G24: 综检后测 | H24: [字节][QTBQC]BD 后测 | I24: Program KILLED BY TIMEOUT Killed by timeout max second 360
A25: 9000 | B25: 6102192404317410 | C25: G220-BM-2 | D25: M5621-I9DD2O-P | E25: 30229008 | F25: 2026-05-12 22:32:05 | G25: 老化测试 | H25: [客户定制][字节] EGS AC测试 10LOOP | I25: PSU0InletTemp 24h ns 100 No Reading PSU0Temp 26h ns 100 No Reading PSU0IIn 2Dh ns 100 No Reading PSU0IOut 2Fh ns 100 No Reading PSU0PIn 82h ns 100 No Reading PSU0POut 84h ns 100 No Reading TotalPower 89h ns 100 No Reading check black keys fail custom toutiao task fail
A26: 9000 | B26: 6102228404322547 | C26: G220B-2G1BxxM-T | D26: SH10T1-3E42GA-S | E26: 30227559 | F26: 2026-05-14 15:17:37 | G26: 初检前测 | H26: [客户定制][字节]黑白名单检查_前测 | I26: 17 05142026 061902 Critical Interrupt PCIEStatus Bus Correctable error BDF 000000 Deasserted 16 05142026 061125 Critical Interrupt PCIEStatus Bus Correctable error BDF 4a0100 Asserted 17 05142026 061902 Critical Interrupt PCIEStatus Bus Correctable error BDF 000000 Deasserted 16 05142026 061125 Critical Interrupt PCIEStatus Bus Correctable error BDF 4a0100 Asserted 17 05142026 061902 Critical Interrupt PCIEStatus Bus Correctable error BDF 000000 Deasserted
A27: 9000 | B27: 6102228404323823 | C27: G220-BM | E27: 30227561 | F27: 2026-05-14 20:37:20 | G27: 老化初检 | H27: [客户定制][字节]BF3串口通信检查 | I27: All serial port test FAIL test result FAIL RESULT FAIL
A28: 9000 | B28: 6102228404316643 | C28: G220B-2G1BxxM-T | D28: SH10T1-3E42GA-S | E28: 30228130 | F28: 2026-05-15 02:47:41 | G28: 老化测试 | H28: [客户定制][字节]EGS混合压测 6H | I28: P7HCUTemp 8Fh ns 725 No Reading
A29: 9000 | B29: 6102228404316644 | C29: G220B-2G1BxxM-T | D29: SH10T1-3E42GA-S | E29: 30228130 | F29: 2026-05-15 04:02:37 | G29: 老化测试 | H29: [客户定制][字节]黑白名单检查_压测 | I29: Fri May 15 035312 2026 ibumad Unknown symbol ibunregisterclient err 22 Fri May 15 035312 2026 ibumad Unknown symbol ibmodifyport err 22 Fri May 15 035312 2026 ibumad Unknown symbol rdmadevaccessnetns err 22 Fri May 15 035312 2026 ibumad Unknown symbol ibinitahattrfromwc err 22 Fri May 15 035312 2026 ibumad Unknown symbol ibregisterclient err 22 Fri May 15 035312 2026 ibumad Unknown symbol ibunregistermadagent err 22 Fri May 15 035312 2026 ibumad Unknown symbol ibpostsendmad err 22
A30: 9000 | B30: 6102228404322545 | C30: G220B-2G1BxxM-T | D30: SH10T1-3E42GA-S | E30: 30227559 | F30: 2026-05-16 10:04:42 | G30: 老化测试 | H30: [字节][千岛湖] BF3 HOST混合压力测试 | I30: Sat May 16 081414 2026 1Hardware Error Hardware error from APEI Generic Hardware Error Source 0 Sat May 16 081414 2026 1Hardware Error It has been corrected by hw and requires no further action Sat May 16 081414 2026 1Hardware Error event severity corrected Sat May 16 081414 2026 1Hardware Error Error 0 type corrected Sat May 16 081414 2026 1Hardware Error sectiontype PCIe error Sat May 16 081414 2026 1Hardware Error porttype 0 PCIe end point Sat May 16 081414 2026 1Hardware Error version
A31: 9000 | B31: 6102228404322553 | C31: G220B-2G1BxxM-T | D31: SH10T1-3E42GA-S | E31: 30227559 | F31: 2026-05-16 11:17:46 | G31: 老化测试 | H31: [字节][千岛湖]AC测试V2 | I31: Sat May 16 111141 2026 ibumad Unknown symbol ibunregisterclient err 22 Sat May 16 111141 2026 ibumad Unknown symbol ibmodifyport err 22 Sat May 16 111141 2026 ibumad Unknown symbol rdmadevaccessnetns err 22 Sat May 16 111141 2026 ibumad Unknown symbol ibinitahattrfromwc err 22 Sat May 16 111141 2026 ibumad Unknown symbol ibregisterclient err 22 Sat May 16 111141 2026 ibumad Unknown symbol ibunregistermadagent err 22 Sat May 16 111141 2026 ibumad Unknown symbol ibpostsendmad err 22
A32: 9000 | B32: 6102264704305235 | C32: S520-BM | D32: SD8S1-I9DS3B-L | E32: 30228543 | F32: 2026-05-08 08:41:44 | G32: 初检前测 | H32: [客户定制][字节]黑白名单检查 | I32: local 6f000 144da80a LinkCap 160GTs x4 LinkSta 160GTs x4 import 6f000 025e0b60 LinkCap 160GTs x4 LinkSta 160GTs x4 compare local pci devices with import information failed PCIeLnx64 command executed failed
A33: 9000 | B33: 6102264704305246 | C33: S520-BM | D33: SD8S1-I9DS3B-L | E33: 30228543 | F33: 2026-05-08 08:41:53 | G33: 初检前测 | H33: [客户定制][字节]黑白名单检查 | I33: local 6f000 144da80a LinkCap 160GTs x4 LinkSta 160GTs x4 import 6f000 025e0b60 LinkCap 160GTs x4 LinkSta 160GTs x4 compare local pci devices with import information failed PCIeLnx64 command executed failed
A34: 9000 | B34: 6102264704305240 | C34: S520-BM | D34: SD8S1-I9DS3B-L | E34: 30228543 | F34: 2026-05-08 08:41:55 | G34: 初检前测 | H34: [客户定制][字节]黑白名单检查 | I34: local 6f000 144da80a LinkCap 160GTs x4 LinkSta 160GTs x4 import 6f000 025e0b60 LinkCap 160GTs x4 LinkSta 160GTs x4 compare local pci devices with import information failed PCIeLnx64 command executed failed
A35: 9000 | B35: 6102264704305250 | C35: S520-BM | D35: SD8S1-I9DS3B-L | E35: 30228543 | F35: 2026-05-08 08:42:01 | G35: 初检前测 | H35: [客户定制][字节]黑白名单检查 | I35: local 6f000 144da80a LinkCap 160GTs x4 LinkSta 160GTs x4 import 6f000 025e0b60 LinkCap 160GTs x4 LinkSta 160GTs x4 compare local pci devices with import information failed PCIeLnx64 command executed failed
A36: 9000 | B36: 6102264704305244 | C36: S520-BM | D36: SD8S1-I9DS3B-L | E36: 30228543 | F36: 2026-05-08 08:42:04 | G36: 初检前测 | H36: [客户定制][字节]黑白名单检查 | I36: local 6f000 144da80a LinkCap 160GTs x4 LinkSta 160GTs x4 import 6f000 025e0b60 LinkCap 160GTs x4 LinkSta 160GTs x4 compare local pci devices with import information failed PCIeLnx64 command executed failed
A37: 9000 | B37: 6102264704305261 | C37: S520-BM | D37: SD8S1-I9DS3B-L | E37: 30228543 | F37: 2026-05-08 09:03:36 | G37: 初检前测 | H37: [客户定制][字节]黑白名单检查 | I37: local 6f000 144da80a LinkCap 160GTs x4 LinkSta 160GTs x4 import 6f000 025e0b60 LinkCap 160GTs x4 LinkSta 160GTs x4 compare local pci devices with import information failed PCIeLnx64 command executed failed
A38: 9000 | B38: 6102228404310023 | C38: G220-BM | E38: 30228124 | F38: 2026-05-08 13:51:31 | G38: 初检前测 | H38: [客户定制][字节]BF3串口通信检查 | I38: All serial port test FAIL test result FAIL RESULT FAIL
A39: 9000 | B39: 6102117004304703 | C39: G220-BM | D39: S80D1-I9ED2M | E39: 30228516 | F39: 2026-05-08 14:10:45 | G39: 老化测试 | H39: [客户定制][字节]混合压测1H与DC测试 | I39: check black list first fail custom toutiao task fail
A40: 9000 | B40: 6102228404304283 | C40: G220-BM | E40: 30228122 | F40: 2026-05-08 15:24:32 | G40: 老化初检 | H40: [客户定制][字节]BF3串口通信检查 | I40: All serial port test FAIL test result FAIL RESULT FAIL
...

Sheet Sheet5
A1: 基地 | B1: SN | C1: 机型名 | D1: 套餐名 | E1: 订单号 | F1: 报错时间 | G1: 当前工站 | H1: 报错测试项 | I1: 日志内容 | J1: 不良维度3 | K1: 维修动作 | L1: 故障分类 | M1: 备注 | N1: 处理人
A2: 9000 | B2: 6102228404301155 | C2: G220B-2G1BxxM-T | D2: SH10T1-3E42GA-S | E2: 30228120 | F2: 2026-05-09 00:56:29 | G2: 老化测试 | H2: [客户定制][字节][TMS/JHS]压力测试 | I2: selog1 p2p c box01 T 300 dir uni 004619600INFO save log to systemsltbm20260509004619log use ooutput to change log location Total Test Result FAILURE BDAASLTrunbmcmd1604cmd run error BDAASLTruntestlist1043P2P unidirectional bandwidth test failed test abort ID Result Description Testing Command 0 FAIL P2P unidirectional bandwidth test systemsltbm showcaselog1 p2p c box01 T 300 dir uni FAIL 20260509 005629 fail RESULT FAIL | J2: 字节_[客户定制][字节][TMS/JHS]压力测试_GPU链路报错 | K2: 重插数据线 | L2: 疑似接触不良问题 | M2: 0
A3: 9000 | B3: 6102228404316673 | C3: G220B-2G1BxxM-T | D3: SH10T1-3E42GA-S | E3: 30228130 | F3: 2026-05-12 11:14:12 | G3: 初检前测 | H3: [客户定制][字节]黑白名单检查_前测 | I3: import 01000 15b3197b LinkCap 320GTs x16 LinkSta 320GTs x16 import 02000 15b3197b LinkCap 320GTs x16 LinkSta 320GTs x16 import 02030 15b3197b LinkCap 320GTs x16 LinkSta 320GTs x16 import 03000 15b3a2dc LinkCap 320GTs x16 LinkSta 320GTs x16 import 03001 15b3a2dc LinkCap 320GTs x16 LinkSta 320GTs x16 import 04000 15b3197b LinkCap 320GTs x16 LinkSta 320GTs x16 import 05000 15b3197b LinkCap 320GTs x2 LinkSta 80GTs x2 | J3: 字节_[客户定制][字节]黑白名单检查_前测_PCIE链路报错 | K3: 更换数据线 | L3: 物料问题 | M3: 0
A4: 9000 | B4: 6102117004309890 | C4: G220-BM | D4: S80D1-I9ED2M | E4: 30228519 | F4: 2026-05-09 11:06:49 | G4: 老化测试 | H4: [客户定制][字节] EGS DC测试 5LOOP | I4: Sat May 9 110443 2026 nvme nvme16 Failed to configure AEN cfg 300 May 9 110512 bytedancehostv13 kernel 6608338 T96 nvme nvme16 Failed to configure AEN cfg 300 15 05092026 025618 Critical Interrupt PCIEStatus Bus Uncorrectable error BDF 000000 Deasserted 12 05092026 013246 Drive Slot Bay NVMEStatus Drive Fault Drive Slot04 Asserted 2a 05092026 030402 Drive Slot Bay NVMEStatus Drive Fault Drive Slot16 Asserted | J4: 字节_[客户定制][字节]混合压测1H与DC测试_硬盘降速 | K4: 更换硬盘 | L4: 疑似接触不良问题 | M4: 0
A5: 9000 | B5: 6102228404304283 | C5: G220B-2G1BxxM-T | D5: SH10T1-3E42GA-S | E5: 30228122 | F5: 2026-05-08 00:50:59 | G5: 初检前测 | H5: [客户定制][字节]黑白名单检查_前测 | I5: 2 05072026 163256 Memory Cpu1MEMG0Hot Critical Overtemperature Deasserted 2 05072026 163256 Memory Cpu1MEMG0Hot Critical Overtemperature Deasserted 5 05072026 163304 Memory Cpu1MEMG0Hot Critical Overtemperature Asserted Cpu1MEMG0Hot 4Ah ok 321 Critical Overtemperature | J5: 停用字节_黑白名单检查_前测_内存超温报错 | K5: 更换主板 | L5: 物料问题 | M5: 0
A6: 9000 | B6: 6102228404317346 | C6: G220B-2G1BxxM-T | D6: SH10T1-3E42GA-S | E6: 30228132 | F6: 2026-05-13 09:32:28 | G6: 初检前测 | H6: [客户定制][字节]黑白名单检查_前测 | I6: import 01000 15b3197b LinkCap 320GTs x16 LinkSta 320GTs x16 import 02000 15b3197b LinkCap 320GTs x16 LinkSta 320GTs x16 import 02030 15b3197b LinkCap 320GTs x16 LinkSta 320GTs x16 import 03000 15b3a2dc LinkCap 320GTs x16 LinkSta 320GTs x16 import 03001 15b3a2dc LinkCap 320GTs x16 LinkSta 320GTs x16 import 04000 15b3197b LinkCap 320GTs x16 LinkSta 320GTs x16 import 05000 15b3197b LinkCap 320GTs x2 LinkSta 80GTs x2 | J6: 字节_[客户定制][字节]黑白名单检查_前测_PCIE链路报错 | K6: 更换retimer卡 | L6: 物料问题 | M6: 0
A7: 9000 | B7: 6102228404304258 | C7: G220B-2G1BxxM-T | D7: SH10T1-3E42GA-S | E7: 30228122 | F7: 2026-05-09 18:46:22 | G7: 老化测试 | H7: [字节][千岛湖] BF3 HOST混合压力测试 | I7: Sat May 9 183703 2026 mce Hardware Error Machine check events logged Sat May 9 183703 2026 1Hardware Error Hardware error from APEI Generic Hardware Error Source 0 Sat May 9 183703 2026 1Hardware Error It has been corrected by hw and requires no further action Sat May 9 183703 2026 1Hardware Error event severity corrected Sat May 9 183703 2026 1Hardware Error Error 0 type corrected Sat May 9 183703 2026 1Hardware Error frutext Socket0 Sat May 9 183703 2026 1Hardware Error sectiontype | J7: 停用字节_[千岛湖] BF3 HOST混合压力测试_CPU报错 | K7: 更换CPU | L7: 疑似接触不良问题 | M7: 0
A8: 9000 | B8: 6102228404301183 | C8: G220B-2G1BxxM-T | D8: SH10T1-3E42GA-S | E8: 30228120 | F8: 2026-05-10 15:01:39 | G8: 老化测试 | H8: [客户定制][字节]EGS混合压测 6H | I8: Sun May 10 144231 2026 mce Hardware Error Machine check events logged Sun May 10 144231 2026 mce Hardware Error Machine check events logged Sun May 10 144231 2026 1Hardware Error Hardware error from APEI Generic Hardware Error Source 0 Sun May 10 144231 2026 1Hardware Error It has been corrected by hw and requires no further action Sun May 10 144231 2026 1Hardware Error event severity corrected Sun May 10 144231 2026 1Hardware Error Error 0 type corrected Sun May 10 144231 2026 1Hardware Error | J8: 停用字节_EGS混合压测-6H_CPU报错 | K8: 更换CPU | L8: 疑似接触不良问题 | M8: 0
A9: 9000 | B9: 6102228404316673 | C9: G220B-2G1BxxM-T | D9: SH10T1-3E42GA-S | E9: 30228130 | F9: 2026-05-12 13:47:32 | G9: 初检前测 | H9: [客户定制][字节]黑白名单检查_前测 | I9: import 01000 15b3197b LinkCap 320GTs x16 LinkSta 320GTs x16 import 02000 15b3197b LinkCap 320GTs x16 LinkSta 320GTs x16 import 02030 15b3197b LinkCap 320GTs x16 LinkSta 320GTs x16 import 03000 15b3a2dc LinkCap 320GTs x16 LinkSta 320GTs x16 import 03001 15b3a2dc LinkCap 320GTs x16 LinkSta 320GTs x16 import 04000 15b3197b LinkCap 320GTs x16 LinkSta 320GTs x16 import 05000 15b3197b LinkCap 320GTs x2 LinkSta 80GTs x2 | J9: 字节_[客户定制][字节]黑白名单检查_前测_PCIE链路报错 | K9: 更换数据线 | L9: 物料问题 | M9: 0
A10: 9000 | B10: 6102228404312978 | C10: G220B-2G1BxxM-T | D10: SH10T1-3E42GA-S | E10: 30228126 | F10: 2026-05-12 17:16:34 | G10: 老化测试 | H10: [字节][千岛湖]AC测试V2 | I10: Tue May 12 170800 2026 mce Hardware Error Machine check events logged Tue May 12 170800 2026 EDAC skx MC6 HANDLING MCE MEMORY ERROR Tue May 12 170800 2026 EDAC MC6 18869 CE memory scrubbing error on CPUSrcID1MC2Chan0DIMM0 channel0 slot0 page0xa073495 offset0xc00 grain32 syndrome0x0 errcode0x00080x00c0 ProcessorSocketId0x1 MemoryControllerId0x2 PhysicalRankId0x0 Row0x38c9 Column0x7f0 Bank0x2 BankGroup0x5 Tue May 12 170800 2026 1Hardware Error Hardware error from APEI Generic Hardware Error Sour | J10: 字节_[字节][千岛湖]AC测试V2_内存Correctable ECC | K10: 更换内存 | L10: 物料问题 | M10: 0
A11: 9000 | B11: 6102228404322539 | C11: G220B-2G1BxxM-T | D11: SH10T1-3E42GA-S | E11: 30227559 | F11: 2026-05-14 08:20:40 | G11: 初检前测 | H11: 硬件信息检查 | I11: PCI Local addr 00009d000 LnkCap 16GTsx4 LnkSta 16GTsx4 equal PCI Local addr 00009e000 LnkCap 16GTsx4 LnkSta 16GTsx4 equal PCI Local addr 0000a0000 LnkCap 16GTsx4 LnkSta 16GTsx4 equal PCI1 Local Count 3 PCI1 check result fail PCI check result fail Disk Disk0 Input SN B5400016 Model SOLIDIGM SSDPF2KX038T1 Count 4 Revision 9CV10511 Disk0 Local Count 3 Disk0 check result fail Disk check result fail | J11: 硬盘数量比对报错（丢盘） | K11: 更换背板 | L11: 物料问题 | M11: 0
A12: 9000 | B12: 6102228404322539 | C12: G220B-2G1BxxM-T | D12: SH10T1-3E42GA-S | E12: 30227559 | F12: 2026-05-14 08:48:44 | G12: 初检前测 | H12: 硬件信息检查 | I12: PCI Local addr 00009d000 LnkCap 16GTsx4 LnkSta 16GTsx4 equal PCI Local addr 00009e000 LnkCap 16GTsx4 LnkSta 16GTsx4 equal PCI Local addr 0000a0000 LnkCap 16GTsx4 LnkSta 16GTsx4 equal PCI1 Local Count 3 PCI1 check result fail PCI check result fail Disk Disk0 Input SN B5400016 Model SOLIDIGM SSDPF2KX038T1 Count 4 Revision 9CV10511 Disk0 Local Count 3 Disk0 check result fail Disk check result fail | J12: 硬盘数量比对报错（丢盘） | K12: 更换背板 | L12: 物料问题 | M12: 0
A13: 9000 | B13: 6102228404322539 | C13: G220B-2G1BxxM-T | D13: SH10T1-3E42GA-S | E13: 30227559 | F13: 2026-05-14 10:03:53 | G13: 初检前测 | H13: 硬件信息检查 | I13: PCI Local addr 00009d000 LnkCap 16GTsx4 LnkSta 16GTsx4 equal PCI Local addr 00009e000 LnkCap 16GTsx4 LnkSta 16GTsx4 equal PCI Local addr 0000a0000 LnkCap 16GTsx4 LnkSta 16GTsx4 equal PCI1 Local Count 3 PCI1 check result fail PCI check result fail Disk Disk0 Input SN B5400016 Model SOLIDIGM SSDPF2KX038T1 Count 4 Revision 9CV10511 Disk0 Local Count 3 Disk0 check result fail Disk check result fail | J13: 硬盘数量比对报错（丢盘） | K13: 更换背板 | L13: 物料问题 | M13: 0
... A41: 9000 | B41: 6102264704305173 | C41: S520-BM | D41: SD8S1-I9DS3B-L | E41: 30228541 | F41: 2026-05-08 09:15:33 | G41: 初检前测 | H41: [客户定制][字节]黑白名单检查 | I41: 12 05082026 010459 Drive Slot Bay HDDStatus Drive Present Drive Slot01 Deasserted 13 05082026 010501 Drive Slot Bay HDDStatus Drive Present Drive Slot05 Deasserted | J41: 停用字节_BytedQC 前测 PreTest_硬盘报错 | K41: 更换硬盘 | L41: 物料问题 | M41: 0

Sheet Sheet2
A1: 基地 | B1: 销售订单 | C1: 生产订单 | D1: L6标识 | E1: 机型 | F1: 主机条码 | G1: 客户序列号 | H1: 资产号 | I1: NG工站 | J1: NG报工人员 | K1: NG报工时间 | L1: 不良现象维度2 | M1: 不良现象维度3 | N1: 维修人员 | O1: 复检人员 | P1: 维修时间 | Q1: 维修维度3 | R1: 二次物料标识 | S1: 涉及部件 | T1: 缺陷责任分类 | U1: 重插物料编码 | V1: 重插物料序号 | W1: 描述 | X1: 物料编码 | Y1: 物料描述 | Z1: OEM料号 | AA1: OEM描述 | AB1: 物料类型 | AC1: 替换前内部/OEM码 | AD1: 替换前原厂码 | AE1: 替换后内部/OEM码 | AF1: 替换后原厂码 | AG1: 非关键件物料序号 | AH1: 槽位 | AI1: 复判人员 | AJ1: 复判结论 | AK1: 复判问题描述 | AL1: 复判输入备注 | AM1: 项目专用 | AN1: RMA复判人员 | AO1: RMA复判结论 | AP1: RMA复判二级 | AQ1: RMA复判三级 | AR1: RMA复判四级 | AS1: 拦截部件压测项 | AT1: 有效性
A2: 9000 | B2: 100001781--60 | C2: 30227588 | E2: 6410 X21 | F2: 6102228104304782 | I2: TXM-OP205初检前测 | J2: 吴伊彬 | K2: 2026-05-08 16:20:08 | L2: 停用字节_[千岛湖]G51_BOX retimer FW 刷新V3 | M2: 停用字节_[千岛湖]G51_BOX retimer FW 刷新V3_FRU信息不全 | N2: 吴伊彬 | O2: 何向丰 桐乡 | P2: 2026-05-08 16:45:46 | Q2: 更换CDFP线 | S2: CDFP线 | T2: 物料问题 | W2: 交叉跟着线走更换CDFP线0,20251129 | AG2: 37002280
A3: 9000 | B3: 100001828--90 | C3: 30228123 | E3: 6410 X21 | F3: 6102228104304179 | I3: TXM-OP210老化测试 | J3: 吴伊彬 | K3: 2026-05-08 08:31:33 | L3: 停用字节_[TMS/JHS]压力测试 | M3: 停用字节_[TMS/JHS]压力测试_压力测试失败 | N3: 吴伊彬 | O3: 何向丰 桐乡 | P3: 2026-05-08 10:44:43 | Q3: 重插GPU卡 | S3: GPU | T3: 疑似接触不良问题 | U3: B2400017 | W3: 交叉 SLOT1/5 | AH3: SLOT1
A4: 9000 | B4: 100001828--90 | C4: 30228123 | E4: 6410 X21 | F4: 6102228104304236 | I4: TXM-OP210老化测试 | J4: 吴伊彬 | K4: 2026-05-09 14:42:42 | L4: 停用字节_[千岛湖]AC测试V2 | M4: 停用字节_[千岛湖]AC测试V2_无温度值 | N4: 吴伊彬 | O4: 何向丰 桐乡 | P4: 2026-05-09 15:43:49 | Q4: 更换GPU卡 | S4: GPU | T4: 物料问题 | W4: 交叉GPU验证跟着走，更换slot5 | X4: B2400017 | Y4: 九华山 火山引擎JHS33211-9 E4x16视频加速卡-B02 | AB4: 04 | AC4: B240001760038145 | AD4: 8SSTA7C06719L7HF63D036D | AE4: B240001760045303 | AF4: 8SSTA7C06719L7HF63D00MG | AH4: slot5 | AI4: 安冰滑 | AJ4: NG | AK4: 系统下无法获取该 GPU 的温度数据。 | AM4: 095TOUTI01
A5: 9000 | B5: 100001828--120 | C5: 30228125 | E5: 6410 X21 | F5: 6102228104309936 | I5: TXM-OP205初检前测 | J5: 吴伊彬 | K5: 2026-05-09 09:21:51 | L5: 停用字节_[千岛湖]BOX FRU信息检查V3 | M5: 停用字节_[千岛湖]BOX FRU信息检查V3_PCIE识别不全 | N5: 吴伊彬 | O5: 何向丰 桐乡 | P5: 2026-05-09 10:39:29 | Q5: 更换GPU卡 | S5: GPU | T5: 物料问题 | W5: 更换slot4 | X5: B2400017 | Y5: 九华山 火山引擎JHS33211-9 E4x16视频加速卡-B02 | AB5: 04 | AC5: B240001760045585 | AD5: 8SSTA7C06719L7HF63D010X | AE5: B240001760045296 | AF5: 8SSTA7C06719L7HF63D0176 | AH5: slot4 | AI5: 安冰滑 | AJ5: NG | AK5: PCIE识别不全，外观无异常 | AM5: 095TOUTI01
A6: 9000 | B6: 100001828--90 | C6: 30228121 | E6: 6410 X21 | F6: 6102228104301008 | I6: TXM-OP210老化测试 | J6: 吴伊彬 | K6: 2026-05-08 15:49:14 | L6: 停用字节_黑白名单检查_压测 | M6: 停用字节_黑白名单检查_压测_XID报错 | N6: 吴伊彬 | O6: 何向丰 桐乡 | P6: 2026-05-08 16:44:35 | Q6: 更换GPU卡 | S6: GPU | T6: 物料问题 | W6: 更换slot10 | X6: B2400017 | Y6: 九华山 火山引擎JHS33211-9 E4x16视频加速卡-B02 | AB6: 04 | AC6: B240001760037758 | AD6: 8SSTA7C06719L7HF63703VG | AE6: B240001760045291 | AF6: 8SSTA7C06719L7HF63D059B | AH6: slot10 | AI6: 安冰滑 | AJ6: NG | AK6: XID报错，外观无异常 | AM6: 095TOUTI01
A7: 9000 | B7: 100001828--120 | C7: 30228131 | E7: 6410 X21 | F7: 6102228104316621 | I7: TXM-OP205初检前测 | J7: 吴伊彬 | K7: 2026-05-12 14:46:24 | L7: 字节_[字节]健康检查 | M7: 字节_[字节]健康检查_GPU降带宽 | N7: 吴伊彬 | O7: 何向丰 桐乡 | P7: 2026-05-12 15:28:32 | Q7: 重插GPU卡 | S7: GPU | T7: 疑似接触不良问题 | U7: B2400017 | W7: 交叉slot10/7 | AH7: slot10
A8: 9000 | B8: 100001828--120 | C8: 30228133 | E8: 6410 X21 | F8: 6102228104317302 | I8: TXM-OP210老化测试 | J8: 吴伊彬 | K8: 2026-05-16 10:46:35 | L8: 字节_[客户定制][字节] DC测试 8LOOP | M8: 字节_[客户定制][字节] DC测试 8LOOP_GPU链路报错 | N8: 吴伊彬 | O8: 何向丰 桐乡 | P8: 2026-05-16 11:25:41 | Q8: 重插GPU卡 | S8: GPU | T8: 疑似接触不良问题 | U8: B2400017 | W8: 交叉SLOT1/10 | AH8: SLOT1
A9: 9000 | B9: 100001781--60 | C9: 30227558 | E9: 6410 X21 | F9: 6102228104322476 | I9: TXM-OP210老化测试 | J9: 吴伊彬 | K9: 2026-05-15 10:18:29 | L9: 字节_[客户定制][字节][TMS/JHS]压力测试 | M9: 字节_[客户定制][字节][TMS/JHS]压力测试_GPU性能不达标 | N9: 吴伊彬 | O9: 何向丰 桐乡 | P9: 2026-05-15 10:57:47 | Q9: 重插GPU卡 | S9: GPU | T9: 疑似接触不良问题 | U9: B2400017 | W9: 交叉slot1/5 | AH9: slot1
A10: 9000 | B10: 100001828--120 | C10: 30228131 | E10: 6410 X21 | F10: 6102228104316630 | I10: TXM-OP205初检前测 | J10: 吴伊彬 | K10: 2026-05-12 09:55:16 | L10: 字节_[字节][千岛湖]BOX FRU信息检查V3 | M10: 字节_[字节][千岛湖]BOX FRU信息检查V3_GPU不识别 | N10: 吴伊彬 | O10: 何向丰 桐乡 | P10: 2026-05-12 10:51:29 | Q10: 重插GPU卡 | S10: GPU | T10: 疑似接触不良问题 | U10: B2400017 | W10: 交叉slot10/7 | AH10: slot10
A11: 9000 | B11: 100001781--60 | C11: 30227560 | E11: 6410 X21 | F11: 6102228104323771 | I11: TXM-OP205初检前测 | J11: 吴伊彬 | K11: 2026-05-15 15:57:45 | L11: 字节_[客户定制][字节]黑白名单检查_前测 | M11: 字节_[客户定制][字节]黑白名单检查_前测_PCIE链路报错 | N11: 何向丰 | O11: 吴伊彬 桐乡 | P11: 2026-05-15 16:00:51 | Q11: 重插GPU卡 | S11: GPU | T11: 疑似接触不良问题 | U11: B2400017 | W11: 交叉SLOT6/4,SLOT7/1 | AH11: SLOT6/7
A12: 9000 | B12: 100001828--120 | C12: 30228131 | E12: 6410 X21 | F12: 6102228104316566 | I12: TXM-OP205初检前测 | J12: 吴伊彬 | K12: 2026-05-12 10:24:15 | L12: 字节_[客户定制][字节]黑白名单检查_前测 | M12: 字节_[客户定制][字节]黑白名单检查_前测_PCIE链路报错 | N12: 吴伊彬 | O12: 何向丰 桐乡 | P12: 2026-05-12 14:53:39 | Q12: 更换数据线 | S12: 数据线 | T12: 物料问题 | W12: 交叉跟着CDFP线走，更换CDFP线7,20251119 | AG12: 37002280
A13: 9000 | B13: 100001828--60 | C13: 30228106 | E13: 6410 X21 | F13: 6102228104323789 | I13: TXM-OP205初检前测 | J13: 吴伊彬 | K13: 2026-05-16 10:48:41 | L13: 字节_[客户定制][字节]黑白名单检查_前测 | M13: 字节_[客户定制][字节]黑白名单检查_前测_PCIE链路报错 | N13: 吴伊彬 | O13: 何向丰 桐乡 | P13: 2026-05-16 11:46:19 | Q13: 重插GPU卡 | S13: GPU | T13: 疑似接触不良问题 | U13: B2400017 | W13: 交叉slot11/7，slot10/5，slot9/3 | AH13: slot11,slot10,slot9
A14: 9000 | B14: 100001781--60 | C14: 30227558 | E14: 6410 X21 | F14: 6102228104322512 | I14: TXM-OP205初检前测 | J14: 吴伊彬 | K14: 2026-05-14 10:58:23 | L14: 字节_[字节][千岛湖]BF3网卡打开主机访问 | M14: 字节_[字节][千岛湖]BF3网卡打开主机访问_CDFP链路丢卡 | N14: 吴伊彬 | O14: 何向丰 桐乡 | P14: 2026-05-14 11:15:57 | Q14: 更换数据线 | S14: 数据线 | T14: 物料问题 | W14: 交叉跟着CDFP线走，更换CDFP线0，20250712 | AG14: 37003507
A15: 9000 | B15: 100001781--60 | C15: 30227558 | E15: 6410 X21 | F15: 6102228104322506 | I15: TXM-OP205初检前测 | J15: 吴伊彬 | K15: 2026-05-14 11:01:08 | L15: 字节_[字节][千岛湖]BF3网卡打开主机访问 | M15: 字节_[字节][千岛湖]BF3网卡打开主机访问_CDFP链路丢卡 | N15: 吴伊彬 | O15: 何向丰 桐乡 | P15: 2026-05-14 11:16:32 | Q15: 更换数据线 | S15: 数据线 | T15: 物料问题 | W15: 交叉跟着CDFP线走，更换CDFP线0，20250712 | AG15: 37003507
A16: 9000 | B16: 100001781--50 | C16: 30227559 | E16: 6210 C21 BOX | F16: 6102228404322539 | H16: 2026-ck-srv-063624 | I16: TXM-OP205初检前测 | J16: 吴伊彬 | K16: 46156.494 | L16: 硬件信息检查 | M16: 硬盘数量比对报错（丢盘） | N16: 吴伊彬 | O16: 何向丰 桐乡 | P16: 2026-05-14 14:01:20 | Q16: 更换背板 | S16: 背板 | T16: 物料问题 | W16: 重插交叉硬盘及数据线无效，交叉跟着背板走，更换硬盘背板 | X16: 24004174 | Y16: BD32G04-8639-U2 C01 硬盘背板(B02-YC)-GT | AB16: 02 | AC16: 2400417430086548 | AE16: 2400417460025637 | AI16: 安冰滑 | AJ16: OK | AK16: 同配置下验证故障未复现 | AM16: 095TOUTI01 | AS16: PCI Local addr 00009e000 LnkCap 16GTsx4 LnkSta 16GTsx4 equal PCI Local addr 00009f000 LnkCap 16GTsx4 LnkSta 16GTsx4 equal PCI Local addr 0000a0000 LnkCap 16GTsx4 LnkSta 16GTsx4 equal PCI1 Local Count 3 PCI1 check result fail PCI check result fail Disk Disk0 Input SN B5400016 Model SOLIDIGM SSDPF2KX038T1 Count 4 Revision 9CV10511 Disk0 Local Count 3 Disk0 check result fail Disk check result fail
A17: 9000 | B17: 100001828--110 | C17: 30228124 | E17: 6210 C21 BOX | F17: 6102228404310028 | H17: 2026-ck-srv-062865 | I17: TXM-OP205初检前测 | J17: 吴伊彬 | K17: 2026-05-09 13:14:20 | L17: 停用字节_黑白名单检查_前测 | M17: 停用字节_黑白名单检查_前测_PCIE链路报错 | N17: 何向丰 | O17: 吴伊彬 桐乡 | P17: 2026-05-09 13:18:55 | Q17: 重插MCIO线 | S17: MCIO线缆 | T17: 疑似接触不良问题 | U17: 37002287 | W17: 重插MCIO线缆J80/J87，交叉J1/J2 | AH17: J87/J80 | AS17: import 01000 15b3197b LinkCap 320GTs x16 LinkSta 320GTs x16 import 02000 15b3197b LinkCap 320GTs x16 LinkSta 320GTs x16 import 02030 15b3197b LinkCap 320GTs x16 LinkSta 320GTs x16 import 03000 15b3a2dc LinkCap 320GTs x16 LinkSta 320GTs x16 import 03001 15b3a2dc LinkCap 320GTs x16 LinkSta 320GTs x16 import 04000 15b3197b LinkCap 320GTs x16 LinkSta 320GTs x16 import 05000 15b3197b LinkCap 320GTs x2 LinkSta 80GTs x2
A18: 9000 | B18: 100001828--110 | C18: 30228124 | E18: 6210 C21 BOX | F18: 6102228404310036 | H18: 2026-ck-srv-062873 | I18: TXM-OP205初检前测 | J18: 吴伊彬 | K18: 2026-05-09 13:13:34 | L18: 停用字节_黑白名单检查_前测 | M18: 停用字节_黑白名单检查_前测_内存ECC报错 | N18: 吴伊彬 | O18: 何向丰 桐乡 | P18: 2026-05-09 13:47:07 | Q18: 更换内存 | S18: 内存 | T18: 物料问题 | W18: 更换P0-C0-D0 | X18: B5000026 | Y18: CX CXMR4E464R8AS DDR5 56R 64G内存-B02 | AB18: 04 | AC18: B500002660419605 | AD18: 8A91502550B021F9F6 | AE18: B500002660424457 | AF18: 8A91502550B0220CEB | AH18: P0-C0-D0 | AI18: 安冰滑 | AJ18: NG | AK18: 内存ECC报错，外观无异常 | AM18: 095TOUTI01 | AS18: Sat May 9 102940 2026 mce Hardware Error Machine check events logged Sat May 9 102940 2026 mce Hardware Error CPU 0 Machine Check 0 Bank 13 8c14694200800090 Sat May 9 102940 2026 mce Hardware Error TSC 0 ADDR 6d542d40 MISC 900024011987086 Sat May 9 102940 2026 mce Hardware Error PROCESSOR 0806f8 TIME 1778293773 SOCKET 0 APIC 0 microcode 2b000643 Sat May 9 102940 2026 mce Hardware Error Machine check events logged Sat May 9 102940 2026 mce Hardware Error CPU 0 Machine Check 0 Bank 13 8c001
A19: 9000 | B19: 100001828--80 | C19: 30228122 | E19: 6210 C21 BOX | F19: 6102228404304283 | H19: 2026-ck-srv-062245 | I19: TXM-OP205初检前测 | J19: 吴伊彬 | K19: 2026-05-08 10:42:33 | L19: 停用字节_黑白名单检查_前测 | M19: 停用字节_黑白名单检查_前测_内存超温报错 | N19: 吴伊彬 | O19: 何向丰 桐乡 | P19: 2026-05-08 13:18:44 | Q19: 更换主板 | S19: 主板 | T19: 物料问题 | W19: 交叉内存及CPU无效，PE指导更换主板 | X19: 24004825 | Y19: YICHUN_60EA32-BD C01 主板(B02 IFX_PFR-HD） | AB19: 04 | AC19: 2400482560000129 | AD19: S123335260700079 | AE19: 2400482560000645 | AF19: S123335261000095 | AM19: 095TOUTI01 | AS19: Test Failure
A20: 9000 | B20: 100001828--110 | C20: 30228126 | E20: 6210 C21 BOX | F20: 6102228404312999 | H20: 2026-ck-srv-063044 | I20: TXM-OP210老化测试 | J20: 吴伊彬 | K20: 2026-05-11 18:23:41 | L20: 字节_[客户定制][字节] DC测试 8LOOP | M20: 字节_[客户定制][字节] DC测试 8LOOP_CPU CE报错 | N20: 吴伊彬 | O20: 何向丰 桐乡 | P20: 2026-05-11 18:47:25 | Q20: 重插CPU | S20: CPU | T20: 疑似接触不良问题 | U20: B6200004 | W20: CPU0 CE报错,重插CPU0 | AH20: CPU0 | AS20: Test Failure
A21: 9000 | B21: 100001828--110 | C21: 30228126 | E21: 6210 C21 BOX | F21: 6102228404312999 | H21: 2026-ck-srv-063044 | I21: TXM-OP210老化测试 | J21: 吴伊彬 | K21: 2026-05-12 09:46:26 | L21: 字节_[客户定制][字节] DC测试 8LOOP | M21: 字节_[客户定制][字节] DC测试 8LOOP_CPU CE报错 | N21: 吴伊彬 | O21: 何向丰 桐乡 | P21: 2026-05-12 10:52:50 | Q21: 重插CPU | S21: CPU | T21: 疑似接触不良问题 | U21: B6200004 | W21: CPU0 CE报错,交叉CPU验证 | AH21: CPU0
A22: 9000 | B22: 100001828--50 | C22: 30228103 | E22: 6210 C21 BOX | F22: 6102228404323859 | H22: 2026-ck-srv-063726 | I22: TXM-OP200老化初检 | J22: 吴伊彬 | K22: 2026-05-15 16:00:17 | L22: 字节_[字节][千岛湖]BOX FRU信息检查V3 | M22: 字节_[字节][千岛湖]BOX FRU信息检查V3_GPU不识别 | N22: 吴伊彬 | O22: 何向丰 桐乡 | P22: 2026-05-15 16:19:07 | Q22: 重插CPU | S22: CPU | T22: 疑似接触不良问题 | U22: B6200004 | W22: 交叉CPU验证 | AH22: CPU0
A23: 9000 | B23: 100001828--50 | C23: 30228103 | E23: 6210 C21 BOX | F23: 6102228404323859 | H23: 2026-ck-srv-063726 | I23: TXM-OP200老化初检 | J23: 吴伊彬 | K23: 2026-05-15 14:04:04 | L23: 字节_[字节][千岛湖]BOX FRU信息检查V3 | M23: 字节_[字节][千岛湖]BOX FRU信息检查V3_GPU不识别 | N23: 吴伊彬 | O23: 何向丰 桐乡 | P23: 2026-05-15 14:20:08 | Q23: 更换数据线 | S23: 数据线 | T23: 物料问题 | W23: 交叉数据线J24/J25复现无效，更换数据线20260317 | AG23: 37002322
A24: 9000 | B24: 100001828--50 | C24: 30228103 | E24: 6210 C21 BOX | F24: 6102228404323859 | H24: 2026-ck-srv-063726 | I24: TXM-OP205初检前测 | J24: 吴伊彬 | K24: 2026-05-15 10:19:20 | L24: 字节_[字节][千岛湖]BOX FRU信息检查V3 | M24: 字节_[字节][千岛湖]BOX FRU信息检查V3_GPU不识别 | N24: 吴伊彬 | O24: 何向丰 桐乡 | P24: 2026-05-15 10:58:52 | Q24: 重插数据线 | S24: 数据线 | T24: 疑似接触不良问题 | U24: 37002322 | W24: 交叉数据线J24/J25 | AS24: Test Failure
A25: 9000 | B25: 100001828--80 | C25: 30228120 | E25: 6210 C21 BOX | F25: 6102228404301183 | H25: 2026-ck-srv-062122 | I25: TXM-OP220老化综检 | J25: 吴伊彬 | K25: 2026-05-15 11:28:17 | L25: 字节_[客户定制][字节]EGS混合压测 6H | M25: 字节_[客户定制][字节]EGS混合压测 6H_CPU CE报错 | N25: 吴伊彬 | O25: 何向丰 桐乡 | P25: 2026-05-15 11:29:22 | Q25: 更换CPU | S25: CPU | T25: 物料问题 | W25: 交叉CPU验证跟着走，更换CPU1 | X25: B6200004 | Y25: Intel 8457C 2.6G 97.5M 48C 350W LJS(B02) | AB25: 04 | AC25: B620000472635431 | AD25: M57018V700420 | AE25: B620000472651092 | AF25: M5964EL500156 | AH25: CPU1 | AI25: 安冰滑 | AJ25: NG | AK25: CPU CE报错，外观无异常 | AM25: 095TOUTI01
A26: 9000 | B26: 100001828--110 | C26: 30228130 | E26: 6210 C21 BOX | F26: 6102228404316644 | H26: 2026-ck-srv-063182 | I26: TXM-OP200老化初检 | J26: 吴伊彬 | K26: 2026-05-11 18:17:20 | L26: 字节_[客户定制][字节]BF3串口通信检查 | M26: 字节_[客户定制][字节]BF3串口通信检查_BF3串口检查失败 | N26: 吴伊彬 | O26: 何向丰 桐乡 | P26: 2026-05-11 18:46:16 | Q26: 重插智能网卡 | S26: BF3智能网卡 | T26: 疑似接触不良问题 | U26: B2400017 | W26: 重插BF3网卡，整理链路 | AH26: PCIE0
A27: 9000 | B27: 100001828--110 | C27: 30228130 | E27: 6210 C21 BOX | F27: 6102228404316641 | H27: 2026-ck-srv-063179 | I27: TXM-OP200老化初检 | J27: 吴伊彬 | K27: 2026-05-11 18:17:58 | L27: 字节_[客户定制][字节]BF3串口通信检查 | M27: 字节_[客户定制][字节]BF3串口通信检查_BF3串口检查失败 | N27: 吴伊彬 | O27: 何向丰 桐乡 | P27: 2026-05-11 18:46:44 | Q27: 重插智能网卡 | S27: BF3智能网卡 | T27: 疑似接触不良问题 | U27: B2400017 | W27: 重插BF3网卡，整理链路 | AH27: PCIE0
A28: 9000 | B28: 100001828--110 | C28: 30228128 | E28: 6210 C21 BOX | F28: 6102228404315812 | H28: 2026-ck-srv-063167 | I28: TXM-OP205初检前测 | J28: 吴伊彬 | K28: 2026-05-11 09:08:09 | L28: 字节_[客户定制][字节]BF3串口通信检查 | M28: 字节_[客户定制][字节]BF3串口通信检查_BF3串口检查失败 | N28: 何向丰 | O28: 吴伊彬 桐乡 | P28: 2026-05-11 09:25:29 | Q28: 重插网卡 | S28: BF3智能网卡 | T28: 疑似接触不良问题 | U28: B2400016 | W28: 重插BF3网卡 | AH28: DPU | AS28: All serial port test FAIL test result FAIL RESULT FAIL
A29: 9000 | B29: 100001828--110 | C29: 30228130 | E29: 6210 C21 BOX | F29: 6102228404316673 | H29: 2026-ck-srv-063211 | I29: TXM-OP205初检前测 | J29: 吴伊彬 | K29: 2026-05-13 11:37:49 | L29: 字节_[客户定制][字节]黑白名单检查_前测 | M29: 字节_[客户定制][字节]黑白名单检查_前测_PCIE链路报错 | N29: 何向丰 | O29: 吴伊彬 桐乡 | P29: 2026-05-13 13:36:32 | Q29: 更换数据线 | S29: 数据线 | T29: 物料问题 | W29: 更换MCIO线缆J24/J25验证 | AG29: 37002322 | AH29: J24/J25 | AS29: Wed May 13 103829 2026 brcmpexnt2 ERROR Invalid Ham Device Context HAM Context 0000000000000000 Wed May 13 103829 2026 brcmpexnt2 ERROR Invalid Ham Device Context HAM Context 0000000000000000 Wed May 13 103829 2026 brcmpexnt2 ERROR Invalid Ham Device Context HAM Context 0000000000000000 Wed May 13 103829 2026 brcmpexnt2 ERROR Invalid Ham Device Context HAM Context 0000000000000000 Wed May 13 103829 2026 brcmpexnt2 ERROR Invalid Ham Device Context HAM Context 0000000000000000
A30: 9000 | B30: 100001828--110 | C30: 30228132 | E30: 6210 C21 BOX | F30: 6102228404317346 | H30: 2026-ck-srv-063397 | I30: TXM-OP205初检前测 | J30: 吴伊彬 | K30: 2026-05-13 11:38:34 | L30: 字节_[客户定制][字节]黑白名单检查_前测 | M30: 字节_[客户定制][字节]黑白名单检查_前测_PCIE链路报错 | N30: 何向丰 | O30: 吴伊彬 桐乡 | P30: 2026-05-13 13:38:26 | Q30: 更换retimer卡 | S30: Retimer卡 | T30: 物料问题 | W30: 交叉retimer卡验证跟着走，更换retimer卡2 | X30: 24003586 | Y30: R1E6-M-U4 A01 Retimer卡(Montage)(B02-QDH) | AB30: 04 | AC30: 2400358660308689 | AD30: C0112602HT307260812642 | AE30: 2400358660299733 | AF30: C0112602HT307260353072 | AH30: retimer2 | AI30: 安冰滑 | AJ30: NG | AK30: PCIE链路报错，外观无异常 | AM30: 095TOUTI01 | AS30: 9 05132026 013501 Power Supply RedundantPSU Fully Redundant Deasserted 7 05132026 013451 Power Unit PowerFault State Asserted ErrorType OTHER Asserted b 05132026 013547 Power Unit PowerFault State Asserted ErrorType OTHER Asserted 7 05132026 013451 Power Unit PowerFault State Asserted ErrorType OTHER Asserted b 05132026 013547 Power Unit PowerFault State Asserted ErrorType OTHER Asserted 8 05132026 013457 Power Supply PSU0Supply Power Supply AC lost A
A31: 9000 | B31: 100001828--110 | C31: 30228130 | E31: 6210 C21 BOX | F31: 6102228404316673 | H31: 2026-ck-srv-063211 | I31: TXM-OP205初检前测 | J31: 吴伊彬 | K31: 2026-05-12 14:45:47 | L31: 字节_[客户定制][字节]黑白名单检查_前测 | M31: 字节_[客户定制][字节]黑白名单检查_前测_PCIE链路报错 | N31: 吴伊彬 | O31: 何向丰 桐乡 | P31: 2026-05-12 15:27:54 | Q31: 重插数据线 | S31: 数据线 | T31: 疑似接触不良问题 | U31: 37002322 | W31: 重插MCIO J24 J25 | AS31: import 01000 15b3197b LinkCap 320GTs x16 LinkSta 320GTs x16 import 02000 15b3197b LinkCap 320GTs x16 LinkSta 320GTs x16 import 02030 15b3197b LinkCap 320GTs x16 LinkSta 320GTs x16 import 03000 15b3a2dc LinkCap 320GTs x16 LinkSta 320GTs x16 import 03001 15b3a2dc LinkCap 320GTs x16 LinkSta 320GTs x16 import 04000 15b3197b LinkCap 320GTs x16 LinkSta 320GTs x16 import 05000 15b3197b LinkCap 320GTs x2 LinkSta 80GTs x2
A32: 9000 | B32: 100001781--50 | C32: 30227559 | E32: 6210 C21 BOX | F32: 6102228404322538 | H32: 2026-ck-srv-063623 | I32: TXM-OP205初检前测 | J32: 吴伊彬 | K32: 2026-05-14 13:23:18 | L32: 字节_[字节][千岛湖]BF3网卡打开主机访问 | M32: 字节_[字节][千岛湖]BF3网卡打开主机访问_CDFP链路丢卡 | N32: 吴伊彬 | O32: 何向丰 桐乡 | P32: 2026-05-14 14:00:17 | Q32: 重插数据线 | S32: 数据线 | T32: 疑似接触不良问题 | U32: 37002322 | W32: 重插MCIO J24 J25 | AS32: Test Failure
A33: 9000 | B33: 100001828--80 | C33: 30228122 | E33: 6210 C21 BOX | F33: 6102228404304258 | H33: 2026-ck-srv-062220 | I33: TXM-OP215综检后测 | J33: 吴伊彬 | K33: 2026-05-14 16:21:38 | L33: 字节_[客户定制][字节]MEMTESTER与FIO测试 | M33: 字节_[客户定制][字节]MEMTESTER与FIO测试_CPU CE报错 | N33: 吴伊彬 | O33: 何向丰 桐乡 | P33: 2026-05-14 16:22:23 | Q33: 更换CPU | S33: CPU | T33: 物料问题 | W33: 交叉CPU验证跟着走，更换当前CPU1 | X33: B6200004 | Y33: Intel 8457C 2.6G 97.5M 48C 350W LJS(B02) | AB33: 04 | AC33: B620000472637215 | AD33: M574631700208 | AE33: B620000472650746 | AF33: M5964EL500383 | AH33: CPU1 | AI33: 安冰滑 | AJ33: NG | AK33: CPU CE报错，外观无异常 | AM33: 095TOUTI01 | AS33: Test Failure
A34: 9000 | B34: 100001826--20 | C34: 30228518 | E34: 6210 C21 | F34: 6102117004304851 | H34: 2026-ck-srv-062767 | I34: TXM-OP205初检前测 | J34: 吴伊彬 | K34: 2026-05-08 15:50:03 | L34: 停用字节_黑白名单检查 | M34: 停用字节_黑白名单_风扇转速异常 | N34: 吴伊彬 | O34: 何向丰 桐乡 | P34: 2026-05-08 16:43:48 | Q34: 更换系统风扇 | S34: 风扇 | T34: 物料问题 | W34: 交叉风扇验证跟着走，更换风扇5 | X34: 3003384 | Y34: 丰衡E20机箱SUNON6056风扇模组（B02定制）R1 | AB34: 02 | AC34: 0300338430779253 | AE34: 0300338430787426 | AH34: 风扇5 | AI34: 安冰滑 | AJ34: NG | AK34: 转速告警 | AM34: 095TOUTI01 | AS34: 2c 05082026 061617 Fan FAN5RSpeed Lower Critical going low Deasserted Reading 768 Threshold 192 RPM 2e 05082026 061658 Fan FAN5RSpeed Lower Critical going low Deasserted Reading 3744 Threshold 192 RPM 30 05082026 061754 Fan FAN5RSpeed Lower Critical going low Deasserted Reading 672 Threshold 192 RPM 32 05082026 061831 Fan FAN5RSpeed Lower Critical going low Deasserted Reading 384 Threshold 192 RPM
A35: 9000 | B35: 100001826--30 | C35: 30228519 | E35: 6210 C21 | F35: 6102117004309917 | H35: 2026-ck-srv-062954 | I35: TXM-OP205初检前测 | J35: 吴伊彬 | K35: 2026-05-09 09:26:01 | L35: 停用字节_黑白名单检查 | M35: 停用字节_黑白名单检查_内存ECC报错 | N35: 吴伊彬 | O35: 何向丰 桐乡 | P35: 2026-05-09 10:40:00 | Q35: 更换内存 | S35: 内存 | T35: 物料问题 | W35: 更换P1_C0_D0 | X35: B5000010 | Y35: MI MTC20F2085S1RC56BD2 D5 56R 32G内存-B02 | AB35: 04 | AC35: B500001060021007 | AD35: 802C0F253552810F3F | AE35: B500001060020952 | AF35: 802C0F2535527407CC | AH35: P1_C0_D0 | AI35: 安冰滑 | AJ35: NG | AK35: 内存ECC报错，外观无异常 | AM35: 095TOUTI01 | AS35: 2e 05082026 183612 Memory P1C0D0Status Correctable ECC Deasserted 35 05082026 191205 Memory P1C0D0Status Memory Device Disabled Deasserted 41 05082026 193655 Memory P1C0D0Status Memory Device Disabled Deasserted 16 05082026 174717 Memory P1C0D0Status Correctable ECC Asserted 2b 05082026 182642 Memory P1C0D0Status Correctable ECC Asserted 2c 05082026 182709 Memory P1C0D0Status Correctable ECC Asserted
A36: 9000 | B36: 100001826--30 | C36: 30228519 | E36: 6210 C21 | F36: 6102117004309890 | H36: 2026-ck-srv-062927 | I36: TXM-OP210老化测试 | J36: 吴伊彬 | K36: 2026-05-09 13:22:41 | L36: 停用字节_EGS DC测试-5LOOP | M36: 停用字节_EGS DC测试-5LOOP_硬盘链路报错 | N36: 吴伊彬 | O36: 何向丰 桐乡 | P36: 2026-05-09 13:46:32 | Q36: 更换硬盘 | S36: 硬盘 | T36: 物料问题 | W36: 交叉跟着硬盘走，更换nvme16 | X36: B5400017 | Y36: SDM SSDPF2KX076T1 7.68T 2.5-E4x4 RSSDB02 | AB36: 03 | AC36: B540001760178375 | AD36: BTAX612209EB7P6DGN | AE36: B540001760178189 | AF36: BTAX61220BKZ7P6DGN | AH36: nvme16 | AI36: 安冰滑 | AJ36: NG | AK36: 厂商复测Fail | AM36: 095TOUTI01 | AS36: Sat May 9 110443 2026 nvme nvme16 Failed to configure AEN cfg 300 May 9 110512 bytedancehostv13 kernel 6608338 T96 nvme nvme16 Failed to configure AEN cfg 300 15 05092026 025618 Critical Interrupt PCIEStatus Bus Uncorrectable error BDF 000000 Deasserted 12 05092026 013246 Drive Slot Bay NVMEStatus Drive Fault Drive Slot04 Asserted 2a 05092026 030402 Drive Slot Bay NVMEStatus Drive Fault Drive Slot16 Asserted
A37: 9000 | B37: 100001826--30 | C37: 30228520 | E37: 6210 C21 | F37: 6102117004312881 | H37: 2026-ck-srv-063126 | I37: TXM-OP210老化测试 | J37: 吴伊彬 | K37: 2026-05-11 11:16:27 | L37: 字节_[客户定制][字节]混合压测1H与DC测试 | M37: 字节_[客户定制][字节]混合压测1H与DC测试_硬盘容量异常 | N37: 吴伊彬 | O37: 何向丰 桐乡 | P37: 2026-05-11 14:11:46 | Q37: 更换硬盘 | S37: 硬盘 | T37: 物料问题 | W37: 更换NVME14 | X37: B5400017 | Y37: SDM SSDPF2KX076T1 7.68T 2.5-E4x4 RSSDB02 | AB37: 03 | AC37: B540001760180302 | AD37: BTAX61220BXV7P6DGN | AE37: B540001760178194 | AF37: BTAX61220BMY7P6DGN | AH37: NVME14 | AI37: 安冰滑 | AJ37: NG | AK37: 厂商复测Fail | AM37: 095TOUTI01 | AS37: check disk smart fail custom toutiao task fail
A38: 9000 | B38: 100001832--20 | C38: 30228541 | E38: 6310 C21L | F38: 6102264704305190 | H38: 2026-ck-srv-062628 | I38: TXM-OP205初检前测 | J38: 吴伊彬 | K38: 2026-05-09 13:09:49 | L38: 停用字节_检查项FRU | M38: 停用字节_检查项FRU_背板FRU读取不到 | N38: 吴伊彬 | O38: 何向丰 桐乡 | P38: 2026-05-09 14:06:47 | Q38: 更换硬盘数据线 | S38: 数据线 | T38: 物料问题 | W38: 交叉数据线验证跟着走，更换上层数据线,20260106 | AG38: 37001772 | AS38: Test Failure
A39: 9000 | B39: 100001832--20 | C39: 30228541 | E39: 6310 C21L | F39: 6102264704305190 | H39: 2026-ck-srv-062628 | I39: TXM-OP205初检前测 | J39: 吴伊彬 | K39: 2026-05-08 14:17:23 | L39: 停用字节_检查项FRU | M39: 停用字节_检查项FRU_背板FRU读取不到 | N39: 吴伊彬 | O39: 何向丰 桐乡 | P39: 2026-05-08 14:49:43 | Q39: 重装背板 | S39: 背板 | T39: 疑似接触不良问题 | U39: 24002986 | W39: 交叉上层背板3/2，重插信号线 | AS39: Test Failure
A40: 9000 | B40: 100001832--20 | C40: 30228541 | E40: 6310 C21L | F40: 6102264704305173 | H40: 2026-ck-srv-062611 | I40: TXM-OP205初检前测 | J40: 吴伊彬 | K40: 2026-05-09 09:19:44 | L40: 停用字节_BytedQC 前测 PreTest | M40: 停用字节_BytedQC 前测 PreTest_硬盘报错 | N40: 吴伊彬 | O40: 何向丰 桐乡 | P40: 2026-05-09 10:38:13 | Q40: 更换硬盘 | S40: 硬盘 | T40: 物料问题 | W40: 交叉跟着硬盘走，更换HDD11 | X40: 54001223 | Y40: 希捷 ST8000NM017B 8T 7.2k 3.5SATA 6G硬盘-B02 | AB40: 03 | AC40: 5400122360100772 | AD40: WWZBJS42 | AE40: 5400122360102771 | AF40: WWZBGHBD | AH40: HDD11 | AI40: 安冰滑 | AJ40: NG | AK40: 硬盘报错，外观无异常 | AM40: 095TOUTI01 | AS40: Test Failure
...

Sheet Sheet3
